Workbook

Sheet 工作表1
A1: Resources Plan
B2: Resurce Count | C2: Man Day | D2: Hiring Period | E2: Cost
A3: {=_xlfn.UNIQUE('Project Planning - B'!G11:G179)} -> Patrick -BA | B3: 1 | C3: =SUMIF('Project Planning - B'!G11:G179, A3,'Project Planning - B'!H11:H179) -> 15 | D3: =TEXT(_xlfn.MINIFS('Project Planning - B'!$I$11:$I$180, 'Project Planning - B'!$G$11:$G$180, A3), "yyyy/mm/dd") & " - " & TEXT(_xlfn.MAXIFS('Project Planning - B'!$J$11:$J$180, 'Project Planning - B'!$G$11:$G$180, A3), "yyyy/mm/dd") -> 2025/11/24 - 2026/01/12
A4: Kent | B4: 1 | C4: =SUMIF('Project Planning - B'!G11:G180, A4,'Project Planning - B'!H11:H180) -> 67 | D4: =TEXT(_xlfn.MINIFS('Project Planning - B'!$I$11:$I$180, 'Project Planning - B'!$G$11:$G$180, A4), "yyyy/mm/dd") & " - " & TEXT(_xlfn.MAXIFS('Project Planning - B'!$J$11:$J$180, 'Project Planning - B'!$G$11:$G$180, A4), "yyyy/mm/dd") -> 2025/12/12 - 2026/08/06 | E4: 0
A5: BA/Testing | B5: 1 | C5: =SUMIF('Project Planning - B'!G11:G181, A5,'Project Planning - B'!H11:H181) -> 136 | D5: =TEXT(_xlfn.MINIFS('Project Planning - B'!$I$11:$I$180, 'Project Planning - B'!$G$11:$G$180, A5), "yyyy/mm/dd") & " - " & TEXT(_xlfn.MAXIFS('Project Planning - B'!$J$11:$J$180, 'Project Planning - B'!$G$11:$G$180, A5), "yyyy/mm/dd") -> 2025/12/31 - 2026/08/17 | E5: 0
A6: FrontEnd | B6: 1 | C6: =SUMIF('Project Planning - B'!G11:G182, A6,'Project Planning - B'!H11:H182) -> 58 | D6: =TEXT(_xlfn.MINIFS('Project Planning - B'!$I$11:$I$180, 'Project Planning - B'!$G$11:$G$180, A6), "yyyy/mm/dd") & " - " & TEXT(_xlfn.MAXIFS('Project Planning - B'!$J$11:$J$180, 'Project Planning - B'!$G$11:$G$180, A6), "yyyy/mm/dd") -> 2025/12/24 - 2026/07/23
A7: New AP Lead | B7: 1 | C7: =SUMIF('Project Planning - B'!G11:G183, A7,'Project Planning - B'!H11:H183) -> 72 | D7: =TEXT(_xlfn.MINIFS('Project Planning - B'!$I$11:$I$180, 'Project Planning - B'!$G$11:$G$180, A7), "yyyy/mm/dd") & " - " & TEXT(_xlfn.MAXIFS('Project Planning - B'!$J$11:$J$180, 'Project Planning - B'!$G$11:$G$180, A7), "yyyy/mm/dd") -> 2026/01/21 - 2026/08/14

Sheet Project Planning - B
C1: DMS Development
B3: TOTAL TASKS | C3: =COUNTA(E11:E1048576) -> 169 | G3: DURATION | H3: =H5-H4+1 -> 267 | J3: Overall Progress
B4: Completed | C4: =COUNTIF(L11:L1048576,B4) -> 0 | G4: START | H4: =MIN(I11:I1048576) -> 45985 | L4: =SUM(#REF!) -> #REF! | N4: Team Member | O4: FTE | P4: Cost / Monthly | T4: Difficulty Level | U4: MD
B5: In progress | C5: =COUNTIF(L11:L1048576,B5) -> 9 | G5: FINISH | H5: =MAX(J11:J1048576) -> 46251 | L5: =SUM(H11:H179) -> 348 | N5: Kent | O5: 1 | Q5: 1 year | T5: Low | U5: 1-2
B6: Not Started | C6: =COUNTIF(L11:L1048576,B6) -> 160 | N6: BA/Testing | O6: 1 | P6: =145000*1.05 -> 152250 | Q6: =P6*12 -> 1827000 | T6: Mid | U6: 3-5
D7: New SA and Engineer training | H7: 1/5/2026 - 1/9/2026 | J7: =1-J5 -> 1 | N7: AP Lead | O7: 1 | Q7: Onboard after Chinese New Year | T7: High | U7: 6-8
N8: FrontEnd1 | O8: 1 | P8: =145000*1.05 -> 152250 | Q8: =P8*12 -> 1827000
N9: Patrick-BA | O9: 0.5
A10: SPRINT | B10: EPIC | C10: FEATURE | D10: TASKS | E10: STORIES | F10: Difficulty Level | G10: RESPONSIBLE | H10: Man Day Required | I10: START | J10: FINISH | K10: DURATION | L10: STATUS
A11: Sprint 1 | B11: Dividend Distribution | C11: Data Mapping, Data Migration & Create Tables in DB | D11: BA | E11: Data Related Detail Requirement Analysis | F11: Mid | G11: Patrick -BA | H11: 3 | I11: 45985 | J11: =WORKDAY(I11,K11) -> 45993 | K11: =H11/$O$9 -> 6 | L11: In progress
A12: Sprint 1 | B12: Dividend Distribution | C12: Data Mapping, Data Migration & Create Tables in DB | D12: BA | E12: Data Related Document Detail Requirement | F12: Mid | G12: Patrick -BA | H12: 3 | I12: =WORKDAY(J11,1) -> 45994 | J12: =WORKDAY(I12,K12) -> 46002 | K12: =H12/$O$9 -> 6 | L12: In progress
A13: Sprint 1 | B13: Dividend Distribution | C13: Data Mapping, Data Migration & Create Tables in DB | D13: Development | E13: Data Mapping - Development | F13: Mid | G13: Kent | H13: 3 | I13: =WORKDAY(J12,1) -> 46003 | J13: =WORKDAY(I13,K13) -> 46008 | K13: =H13/$O$5 -> 3 | L13: In progress
A14: Sprint 1 | B14: Dividend Distribution | C14: Data Mapping, Data Migration & Create Tables in DB | D14: Development | E14: Data Migration - Development | F14: High | G14: Kent | H14: 5 | I14: =WORKDAY(J13,1) -> 46009 | J14: =WORKDAY(I14,K14) -> 46016 | K14: =H14/$O$5 -> 5 | L14: Not Started
A15: Sprint 2 | B15: Dividend Distribution | C15: Data Mapping, Data Migration & Create Tables in DB | D15: Development | E15: Create Tables in DB - Development | F15: Low | G15: Kent | H15: 2 | I15: =WORKDAY(J14,1) -> 46017 | J15: =WORKDAY(I15,K15) -> 46021 | K15: =H15/$O$5 -> 2 | L15: Not Started
A16: Sprint 2 | B16: Dividend Distribution | C16: Data Mapping, Data Migration & Create Tables in DB | D16: Testing | E16: Data Related QA - unit testing | F16: Mid | G16: BA/Testing | H16: 3 | I16: =WORKDAY(J15,1) -> 46022 | J16: =WORKDAY(I16,K16) -> 46027 | K16: =H16/$O$5 -> 3 | L16: Not Started
A17: Sprint 2 | B17: Dividend Distribution | C17: Maintain Distributable Balance 可分配餘額維護作業 | D17: BA | E17: Maintain Distributable Balance Detail Requirement Analysis | F17: {=_xlfn.IFS(H17="","", H17<=2,"Low", H17<=5,"Mid", H17<=8,"High", TRUE,"Out of Range")} -> Low | G17: Patrick -BA | H17: 1.5 | I17: =WORKDAY(J12,1) -> 46003 | J17: =WORKDAY(I17,K17) -> 46008 | K17: =H17/$O$9 -> 3 | L17: In progress
A18: Sprint 2 | B18: Dividend Distribution | C18: Maintain Distributable Balance 可分配餘額維護作業 | D18: BA | E18: Maintain Distributable Document Detail Requirement | F18: {=_xlfn.IFS(H18="","", H18<=2,"Low", H18<=5,"Mid", H18<=8,"High", TRUE,"Out of Range")} -> Low | G18: Patrick -BA | H18: 1.5 | I18: =WORKDAY(J17,1) -> 46009 | J18: =WORKDAY(I18,K18) -> 46014 | K18: =H18/$O$9 -> 3 | L18: In progress
A19: Sprint 2 | B19: Dividend Distribution | C19: Maintain Distributable Balance 可分配餘額維護作業 | D19: Development | E19: Maintain Distributable Balance - Development 1 | F19: {=_xlfn.IFS(H19="","", H19<=2,"Low", H19<=5,"Mid", H19<=8,"High", TRUE,"Out of Range")} -> Low | G19: FrontEnd | H19: 1 | I19: =WORKDAY(J18,1) -> 46015 | J19: =WORKDAY(I19,K19) -> 46016 | K19: =H19/$O$5 -> 1 | L19: Not Started
A20: Sprint 3 | B20: Dividend Distribution | C20: Maintain Distributable Balance 可分配餘額維護作業 | D20: Development | E20: Maintain Distributable Balance - Development 2 | F20: {=_xlfn.IFS(H20="","", H20<=2,"Low", H20<=5,"Mid", H20<=8,"High", TRUE,"Out of Range")} -> High | G20: Kent | H20: 7 | I20: =WORKDAY(J15,1) -> 46022 | J20: =WORKDAY(I20,K20) -> 46031 | K20: =H20/$O$5 -> 7 | L20: Not Started
A21: Sprint 3 | B21: Dividend Distribution | C21: Maintain Distributable Balance 可分配餘額維護作業 | D21: Testing | E21: Maintain Distributable Balance QA - unit testing | F21: {=_xlfn.IFS(H21="","", H21<=2,"Low", H21<=5,"Mid", H21<=8,"High", TRUE,"Out of Range")} -> Mid | G21: BA/Testing | H21: 3 | I21: =WORKDAY(J20,1) -> 46034 | J21: =WORKDAY(I21,K21) -> 46037 | K21: =H21/$O$5 -> 3 | L21: Not Started
A22: Sprint 3 | B22: Dividend Distribution | C22: Domestic Dividend Information Inquiry 境內配息資訊查詢作業 | D22: BA | E22: Domestic Dividend Information Inquiry Detail Requirement Analysis | F22: {=_xlfn.IFS(H22="","", H22<=2,"Low", H22<=5,"Mid", H22<=8,"High", TRUE,"Out of Range")} -> Low | G22: Patrick -BA | H22: 1.5 | I22: =WORKDAY(J18,1) -> 46015 | J22: =WORKDAY(I22,K22) -> 46020 | K22: =H22/$O$9 -> 3 | L22: In progress
A23: Sprint 3 | B23: Dividend Distribution | C23: Domestic Dividend Information Inquiry 境內配息資訊查詢作業 | D23: BA | E23: Domestic Dividend Information Inquiry Document Detail Requirement | F23: {=_xlfn.IFS(H23="","", H23<=2,"Low", H23<=5,"Mid", H23<=8,"High", TRUE,"Out of Range")} -> Low | G23: Patrick -BA | H23: 1.5 | I23: =WORKDAY(J19,1) -> 46017 | J23: =WORKDAY(I23,K23) -> 46022 | K23: =H23/$O$9 -> 3 | L23: In progress
A24: Sprint 4 | B24: Dividend Distribution | C24: Domestic Dividend Information Inquiry 境內配息資訊查詢作業 | D24: Development | E24: Domestic Dividend Information Inquiry - Development 1 | F24: {=_xlfn.IFS(H24="","", H24<=2,"Low", H24<=5,"Mid", H24<=8,"High", TRUE,"Out of Range")} -> Mid | G24: FrontEnd | H24: 4 | I24: =WORKDAY(J23,1) -> 46023 | J24: =WORKDAY(I24,K24) -> 46029 | K24: =H24/$O$5 -> 4 | L24: Not Started
A25: Sprint 4 | B25: Dividend Distribution | C25: Domestic Dividend Information Inquiry 境內配息資訊查詢作業 | D25: Development | E25: Domestic Dividend Information Inquiry - Development 2 | F25: {=_xlfn.IFS(H25="","", H25<=2,"Low", H25<=5,"Mid", H25<=8,"High", TRUE,"Out of Range")} -> Mid | G25: Kent | H25: 4 | I25: =WORKDAY(J20,1) -> 46034 | J25: =WORKDAY(I25,K25) -> 46038 | K25: =H25/$O$5 -> 4 | L25: Not Started
A26: Sprint 5 | B26: Dividend Distribution | C26: Domestic Dividend Information Inquiry 境內配息資訊查詢作業 | D26: Testing | E26: Domestic Dividend Information Inquiry QA - unit testing | F26: {=_xlfn.IFS(H26="","", H26<=2,"Low", H26<=5,"Mid", H26<=8,"High", TRUE,"Out of Range")} -> Low | G26: BA/Testing | H26: 2 | I26: =WORKDAY(J25,1) -> 46041 | J26: =WORKDAY(I26,K26) -> 46043 | K26: =H26/$O$5 -> 2 | L26: Not Started
A27: Sprint 3 | B27: Dividend Distribution | C27: Upload Domestic Dividend Composition Info to EC 境內配息組成資訊上傳EC | D27: BA | E27: Upload Domestic Dividend Composition Info to EC - Detail Requirement Analysis | F27: {=_xlfn.IFS(H27="","", H27<=2,"Low", H27<=5,"Mid", H27<=8,"High", TRUE,"Out of Range")} -> Low | G27: Patrick -BA | H27: 1.5 | I27: =WORKDAY(J23,1) -> 46023 | J27: =WORKDAY(I27,K27) -> 46028 | K27: =H27/$O$9 -> 3 | L27: In progress
A28: Sprint 3 | B28: Dividend Distribution | C28: Upload Domestic Dividend Composition Info to EC 境內配息組成資訊上傳EC | D28: BA | E28: Upload Domestic Dividend Composition Info to EC - Document Detail Requirement | F28: {=_xlfn.IFS(H28="","", H28<=2,"Low", H28<=5,"Mid", H28<=8,"High", TRUE,"Out of Range")} -> Low | G28: Patrick -BA | H28: 1.5 | I28: =WORKDAY(J27,1) -> 46029 | J28: =WORKDAY(I28,K28) -> 46034 | K28: =H28/$O$9 -> 3 | L28: In progress
A29: Sprint 5 | B29: Dividend Distribution | C29: Upload Domestic Dividend Composition Info to EC 境內配息組成資訊上傳EC | D29: Development | E29: Upload Domestic Dividend Composition Info to EC - Development 1 | F29: {=_xlfn.IFS(H29="","", H29<=2,"Low", H29<=5,"Mid", H29<=8,"High", TRUE,"Out of Range")} -> Mid | G29: FrontEnd | H29: 4 | I29: =WORKDAY(J24,1) -> 46030 | J29: =WORKDAY(I29,K29) -> 46036 | K29: =H29/$O$5 -> 4 | L29: Not Started
A30: Sprint 5 | B30: Dividend Distribution | C30: Upload Domestic Dividend Composition Info to EC 境內配息組成資訊上傳EC | D30: Development | E30: Upload Domestic Dividend Composition Info to EC - Development 2 | F30: {=_xlfn.IFS(H30="","", H30<=2,"Low", H30<=5,"Mid", H30<=8,"High", TRUE,"Out of Range")} -> Mid | G30: Kent | H30: 4 | I30: =WORKDAY(J25,1) -> 46041 | J30: =WORKDAY(I30,K30) -> 46045 | K30: =H30/$O$5 -> 4 | L30: Not Started
A31: Sprint 6 | B31: Dividend Distribution | C31: Upload Domestic Dividend Composition Info to EC 境內配息組成資訊上傳EC | D31: Testing | E31: Upload Domestic Dividend Composition Info to EC QA - unit testing | F31: {=_xlfn.IFS(H31="","", H31<=2,"Low", H31<=5,"Mid", H31<=8,"High", TRUE,"Out of Range")} -> Low | G31: BA/Testing | H31: 1 | I31: =WORKDAY(J30,1) -> 46048 | J31: 46048 | K31: 1 | L31: Not Started
A32: Sprint 1 | B32: Mandate | C32: Data Mapping, Data Migration & Create Tables in DB | D32: BA | E32: Data Mapping, Data Migration & Create Tables in DB Requirement Analysis | F32: {=_xlfn.IFS(H32="","", H32<=2,"Low", H32<=5,"Mid", H32<=8,"High", TRUE,"Out of Range")} -> Mid | G32: BA/Testing | H32: 3 | I32: 46035 | J32: 46037 | K32: =H32/$O$6 -> 3 | L32: Not Started
A33: Sprint 2 | B33: Mandate | C33: Data Mapping, Data Migration & Create Tables in DB | D33: BA | E33: Data Mapping, Data Migration & Create Tables in DB Requirement | F33: {=_xlfn.IFS(H33="","", H33<=2,"Low", H33<=5,"Mid", H33<=8,"High", TRUE,"Out of Range")} -> Mid | G33: BA/Testing | H33: 3 | I33: 46038 | J33: 46042 | K33: =H33/$O$6 -> 3 | L33: Not Started
A34: Sprint 2 | B34: Mandate | C34: Data Mapping, Data Migration & Create Tables in DB | D34: Development | E34: Data Mapping - Development | F34: {=_xlfn.IFS(H34="","", H34<=2,"Low", H34<=5,"Mid", H34<=8,"High", TRUE,"Out of Range")} -> Mid | G34: New AP Lead | H34: 4 | I34: 46043 | J34: 46048 | K34: =H34/$O$7 -> 4 | L34: Not Started
A35: Sprint 3 | B35: Mandate | C35: Data Mapping, Data Migration & Create Tables in DB | D35: Development | E35: Data Migration - Development | F35: {=_xlfn.IFS(H35="","", H35<=2,"Low", H35<=5,"Mid", H35<=8,"High", TRUE,"Out of Range")} -> Mid | G35: New AP Lead | H35: 4 | I35: 46049 | J35: 46052 | K35: =H35/$O$7 -> 4 | L35: Not Started
A36: Sprint 4 | B36: Mandate | C36: Data Mapping, Data Migration & Create Tables in DB | D36: Development | E36: Create Tables in DB - Development | F36: {=_xlfn.IFS(H36="","", H36<=2,"Low", H36<=5,"Mid", H36<=8,"High", TRUE,"Out of Range")} -> Low | G36: New AP Lead | H36: 2 | I36: 46055 | J36: 46056 | K36: =H36/$O$7 -> 2 | L36: Not Started
A37: Sprint 5 | B37: Mandate | C37: Data Mapping, Data Migration & Create Tables in DB | D37: Testing | E37: Data Related QA - unit testing | F37: {=_xlfn.IFS(H37="","", H37<=2,"Low", H37<=5,"Mid", H37<=8,"High", TRUE,"Out of Range")} -> Mid | G37: BA/Testing | H37: 3 | I37: 46057 | J37: 46059 | K37: =H37/$O$5 -> 3 | L37: Not Started
A38: Sprint 4 | B38: Mandate | C38: FAS 8111 Mandate Client Information Maintenance 全委委託人資料維護 | D38: BA | E38: Mandate Client Information Maintenance Requirement Analysis | F38: {=_xlfn.IFS(H38="","", H38<=2,"Low", H38<=5,"Mid", H38<=8,"High", TRUE,"Out of Range")} -> Low | G38: BA/Testing | H38: 2 | I38: 46043 | J38: 46044 | K38: =H38/$O$7 -> 2 | L38: Not Started
A39: Sprint 4 | B39: Mandate | C39: FAS 8111 Mandate Client Information Maintenance 全委委託人資料維護 | D39: BA | E39: Mandate Client Information Maintenance Requirement | F39: {=_xlfn.IFS(H39="","", H39<=2,"Low", H39<=5,"Mid", H39<=8,"High", TRUE,"Out of Range")} -> Low | G39: BA/Testing | H39: 2 | I39: 46045 | J39: 46045 | K39: 1 | L39: Not Started
A40: Sprint 4 | B40: Mandate | C40: FAS 8111 Mandate Client Information Maintenance 全委委託人資料維護 | D40: Development | E40: Mandate Client Information Maintenance - Development 1 | F40: {=_xlfn.IFS(H40="","", H40<=2,"Low", H40<=5,"Mid", H40<=8,"High", TRUE,"Out of Range")} -> Low | G40: FrontEnd | H40: 2 | I40: 46049 | J40: 46050 | K40: =H40/$O$8 -> 2 | L40: Not Started
A41: Sprint 5 | B41: Mandate | C41: FAS 8111 Mandate Client Information Maintenance 全委委託人資料維護 | D41: Development | E41: Mandate Client Information Maintenance - Development 2 | F41: {=_xlfn.IFS(H41="","", H41<=2,"Low", H41<=5,"Mid", H41<=8,"High", TRUE,"Out of Range")} -> High | G41: New AP Lead | H41: 8 | I41: 46057 | J41: 46066 | K41: =H41/$O$7 -> 8 | L41: Not Started
...

Sheet Project Planning - A
C1: DMS Development
B3: TOTAL TASKS | C3: =COUNTA(E18:E1048576) -> 199 | F3: DURATION | G3: =G5-G4+1 -> 762 | I3: Overall Progress | M3: Team Member | N3: FTE | O3: Cost / Monthly | P3: 1 year
B4: Completed | C4: =COUNTIF(K18:K1048576,B4) -> 2 | F4: START | G4: =MIN(H12:H1048576) -> 45717 | K4: =SUM(G12:G17) -> 24 | M4: Kent | N4: 1
B5: In progress | C5: =COUNTIF(K18:K1048576,B5) -> 7 | F5: FINISH | G5: =MAX(I12:I1048576) -> 46478 | K5: =SUM(G12:G216) -> 419 | M5: AP Lead | N5: 1
B6: Not Started | C6: =COUNTIF(K18:K1048576,B6) -> 191 | M6: FrontEnd1 | N6: 1 | O6: =145000*1.05 -> 152250 | P6: =O6*12 -> 1827000
I7: =1-I5 -> 1 | K7: =K4/K5 -> 0.057279236 | M7: Patrick-BA | N7: 0.5
A11: SPRINT | B11: EPIC | C11: FEATURE | D11: TASKS | E11: STORIES | F11: RESPONSIBLE | G11: Man Day Required | H11: START | I11: FINISH | J11: DURATION | K11: STATUS
A12: Sprint 0 | B12: Shareholders' Meeting & Management | C12: Data Mapping, Data Migration & Create Tables in DB | D12: BA | E12: Data Mapping, Data Migration & Create Tables in DB Requirement Analysis | F12: BA | G12: 3 | H12: 45915 | I12: =WORKDAY(H12,J12) -> 45918 | J12: =G12/$N$4 -> 3 | K12: Completed
A13: Sprint 0 | B13: Shareholders' Meeting & Management | C13: Data Mapping, Data Migration & Create Tables in DB | D13: BA | E13: Data Mapping, Data Migration & Create Tables in DB Requirement | F13: BA | G13: 3 | H13: =WORKDAY(I12,1) -> 45919 | I13: =WORKDAY(H13,J13) -> 45924 | J13: =G13/$N$4 -> 3 | K13: Completed
A14: Sprint 0 | B14: Shareholders' Meeting & Management | C14: Data Mapping, Data Migration & Create Tables in DB | D14: Development | E14: Data Mapping - Development | F14: Kent | G14: 5 | H14: =WORKDAY(I13,1) -> 45925 | I14: =WORKDAY(H14,J14) -> 45932 | J14: =G14/$N$4 -> 5 | K14: Completed
A15: Sprint 0 | B15: Shareholders' Meeting & Management | C15: Data Mapping, Data Migration & Create Tables in DB | D15: Development | E15: Data Migration - Development | F15: Kent | G15: 5 | H15: =WORKDAY(I14,1) -> 45933 | I15: =WORKDAY(H15,J15) -> 45940 | J15: =G15/$N$4 -> 5 | K15: Completed
A16: Sprint 0 | B16: Shareholders' Meeting & Management | C16: Data Mapping, Data Migration & Create Tables in DB | D16: Development | E16: Create Tables in DB - Development | F16: Kent | G16: 5 | H16: =WORKDAY(I15,1) -> 45943 | I16: =WORKDAY(H16,J16) -> 45950 | J16: =G16/$N$4 -> 5 | K16: Completed
A17: Sprint 0 | B17: Shareholders' Meeting & Management | C17: Data Mapping, Data Migration & Create Tables in DB | D17: QA | E17: Data Related QA - unit testing | F17: QA | G17: 3 | H17: =WORKDAY(I16,1) -> 45951 | I17: =WORKDAY(H17,J17) -> 45954 | J17: =G17/$N$4 -> 3 | K17: Completed
A18: Sprint 1 | B18: Dividend Distribution | C18: Data Mapping, Data Migration & Create Tables in DB | D18: BA | E18: Data Related Detail Requirement Analysis | F18: Patrick-BA | G18: 3 | H18: 45985 | I18: =WORKDAY(H18,J18) -> 45993 | J18: =G18/$N$7 -> 6 | K18: Completed
A19: Sprint 1 | B19: Dividend Distribution | C19: Data Mapping, Data Migration & Create Tables in DB | D19: BA | E19: Data Related Document Detail Requirement | F19: Patrick-BA | G19: 3 | H19: =WORKDAY(I18,1) -> 45994 | I19: =WORKDAY(H19,J19) -> 46002 | J19: =G19/$N$7 -> 6 | K19: Completed
A20: Sprint 1 | B20: Dividend Distribution | C20: Data Mapping, Data Migration & Create Tables in DB | D20: Development | E20: Data Mapping - Development | F20: Kent | G20: 3 | H20: =WORKDAY(I19,1) -> 46003 | I20: =WORKDAY(H20,J20) -> 46008 | J20: =G20/$N$4 -> 3 | K20: In progress
A21: Sprint 1 | B21: Dividend Distribution | C21: Data Mapping, Data Migration & Create Tables in DB | D21: Development | E21: Data Migration - Development | F21: Kent | G21: 5 | H21: =WORKDAY(I20,1) -> 46009 | I21: =WORKDAY(H21,J21) -> 46016 | J21: =G21/$N$4 -> 5 | K21: Not Started
A22: Sprint 2 | B22: Dividend Distribution | C22: Data Mapping, Data Migration & Create Tables in DB | D22: Development | E22: Create Tables in DB - Development | F22: Kent | G22: 2 | H22: =WORKDAY(I21,1) -> 46017 | I22: =WORKDAY(H22,J22) -> 46021 | J22: =G22/$N$4 -> 2 | K22: Not Started
A23: Sprint 2 | B23: Dividend Distribution | C23: Data Mapping, Data Migration & Create Tables in DB | D23: QA | E23: Data Related QA - unit testing | F23: Kent | G23: 3 | H23: =WORKDAY(I22,1) -> 46022 | I23: =WORKDAY(H23,J23) -> 46027 | J23: =G23/$N$4 -> 3 | K23: Not Started
A24: Sprint 2 | B24: Dividend Distribution | C24: Maintain Distributable Balance 可分配餘額維護作業 | D24: BA | E24: Maintain Distributable Balance Detail Requirement Analysis | F24: Patrick-BA | G24: 1.5 | H24: =WORKDAY(I19,1) -> 46003 | I24: =WORKDAY(H24,J24) -> 46008 | J24: =G24/$N$7 -> 3 | K24: In progress
A25: Sprint 2 | B25: Dividend Distribution | C25: Maintain Distributable Balance 可分配餘額維護作業 | D25: BA | E25: Maintain Distributable Document Detail Requirement | F25: Patrick-BA | G25: 1.5 | H25: =WORKDAY(I24,1) -> 46009 | I25: =WORKDAY(H25,J25) -> 46014 | J25: =G25/$N$7 -> 3 | K25: In progress
A26: Sprint 2 | B26: Dividend Distribution | C26: Maintain Distributable Balance 可分配餘額維護作業 | D26: Development | E26: Maintain Distributable Balance - Development 1 | F26: FrontEnd | G26: 1 | H26: =WORKDAY(I25,1) -> 46015 | I26: =WORKDAY(H26,J26) -> 46016 | J26: =G26/$N$4 -> 1 | K26: Not Started
A27: Sprint 3 | B27: Dividend Distribution | C27: Maintain Distributable Balance 可分配餘額維護作業 | D27: Development | E27: Maintain Distributable Balance - Development 2 | F27: Kent | G27: 7 | H27: =WORKDAY(I22,1) -> 46022 | I27: =WORKDAY(H27,J27) -> 46031 | J27: =G27/$N$4 -> 7 | K27: Not Started
A28: Sprint 3 | B28: Dividend Distribution | C28: Maintain Distributable Balance 可分配餘額維護作業 | D28: QA | E28: Maintain Distributable Balance QA - unit testing | F28: Kent | G28: 3 | H28: =WORKDAY(I27,1) -> 46034 | I28: =WORKDAY(H28,J28) -> 46037 | J28: =G28/$N$4 -> 3 | K28: Not Started
A29: Sprint 3 | B29: Dividend Distribution | C29: Domestic Dividend Information Inquiry 境內配息資訊查詢作業 | D29: BA | E29: Domestic Dividend Information Inquiry Detail Requirement Analysis | F29: Patrick-BA | G29: 1.5 | H29: =WORKDAY(I25,1) -> 46015 | I29: =WORKDAY(H29,J29) -> 46020 | J29: =G29/$N$7 -> 3 | K29: In progress
A30: Sprint 3 | B30: Dividend Distribution | C30: Domestic Dividend Information Inquiry 境內配息資訊查詢作業 | D30: BA | E30: Domestic Dividend Information Inquiry Document Detail Requirement | F30: Patrick-BA | G30: 1.5 | H30: =WORKDAY(I26,1) -> 46017 | I30: =WORKDAY(H30,J30) -> 46022 | J30: =G30/$N$7 -> 3 | K30: In progress
A31: Sprint 4 | B31: Dividend Distribution | C31: Domestic Dividend Information Inquiry 境內配息資訊查詢作業 | D31: Development | E31: Domestic Dividend Information Inquiry - Development 1 | F31: FrontEnd | G31: 4 | H31: =WORKDAY(I30,1) -> 46023 | I31: =WORKDAY(H31,J31) -> 46029 | J31: =G31/$N$4 -> 4 | K31: Not Started
A32: Sprint 4 | B32: Dividend Distribution | C32: Domestic Dividend Information Inquiry 境內配息資訊查詢作業 | D32: Development | E32: Domestic Dividend Information Inquiry - Development 2 | F32: Kent | G32: 4 | H32: =WORKDAY(I28,1) -> 46038 | I32: =WORKDAY(H32,J32) -> 46044 | J32: =G32/$N$4 -> 4 | K32: Not Started
A33: Sprint 5 | B33: Dividend Distribution | C33: Domestic Dividend Information Inquiry 境內配息資訊查詢作業 | D33: QA | E33: Domestic Dividend Information Inquiry QA - unit testing | F33: Kent | G33: 2 | H33: =WORKDAY(I32,1) -> 46045 | I33: =WORKDAY(H33,J33) -> 46049 | J33: =G33/$N$4 -> 2 | K33: Not Started
A34: Sprint 3 | B34: Dividend Distribution | C34: Upload Domestic Dividend Composition Info to EC 境內配息組成資訊上傳EC | D34: BA | E34: Upload Domestic Dividend Composition Info to EC - Detail Requirement Analysis | F34: Patrick-BA | G34: 1.5 | H34: =WORKDAY(I30,1) -> 46023 | I34: =WORKDAY(H34,J34) -> 46028 | J34: =G34/$N$7 -> 3 | K34: In progress
A35: Sprint 3 | B35: Dividend Distribution | C35: Upload Domestic Dividend Composition Info to EC 境內配息組成資訊上傳EC | D35: BA | E35: Upload Domestic Dividend Composition Info to EC - Document Detail Requirement | F35: Patrick-BA | G35: 1.5 | H35: =WORKDAY(I34,1) -> 46029 | I35: =WORKDAY(H35,J35) -> 46034 | J35: =G35/$N$7 -> 3 | K35: In progress
A36: Sprint 5 | B36: Dividend Distribution | C36: Upload Domestic Dividend Composition Info to EC 境內配息組成資訊上傳EC | D36: Development | E36: Upload Domestic Dividend Composition Info to EC - Development 1 | F36: FrontEnd | G36: 4 | H36: =WORKDAY(I31,1) -> 46030 | I36: =WORKDAY(H36,J36) -> 46036 | J36: =G36/$N$4 -> 4 | K36: Not Started
A37: Sprint 5 | B37: Dividend Distribution | C37: Upload Domestic Dividend Composition Info to EC 境內配息組成資訊上傳EC | D37: Development | E37: Upload Domestic Dividend Composition Info to EC - Development 2 | F37: Kent | G37: 4 | H37: =WORKDAY(I33,1) -> 46050 | I37: =WORKDAY(H37,J37) -> 46056 | J37: =G37/$N$4 -> 4 | K37: Not Started
A38: Sprint 6 | B38: Dividend Distribution | C38: Upload Domestic Dividend Composition Info to EC 境內配息組成資訊上傳EC | D38: QA | E38: Upload Domestic Dividend Composition Info to EC QA - unit testing | F38: Kent | G38: 2 | H38: =WORKDAY(I37,1) -> 46057 | I38: =WORKDAY(H38,J38) -> 46059 | J38: =G38/$N$4 -> 2 | K38: Not Started
A39: Sprint 1 | B39: Mandate | C39: Data Mapping, Data Migration & Create Tables in DB | D39: BA | E39: Data Mapping, Data Migration & Create Tables in DB Requirement Analysis | F39: New AP Lead | G39: 3 | H39: 46022 | I39: =WORKDAY(H39,J39) -> 46027 | J39: =IF(F39="New AP Lead", G39/$N$5, IF(F39="Kent", G39/$N$4, "")) -> 3 | K39: Not Started
A40: Sprint 2 | B40: Mandate | C40: Data Mapping, Data Migration & Create Tables in DB | D40: BA | E40: Data Mapping, Data Migration & Create Tables in DB Requirement | F40: New AP Lead | G40: 3 | H40: =WORKDAY(I39,1) -> 46028 | I40: =WORKDAY(H40,J40) -> 46031 | J40: =IF(F40="New AP Lead", G40/$N$5, IF(F40="Kent", G40/$N$4, "")) -> 3 | K40: Not Started
A41: Sprint 2 | B41: Mandate | C41: Data Mapping, Data Migration & Create Tables in DB | D41: Development | E41: Data Mapping - Development | F41: New AP Lead | G41: 4 | H41: =WORKDAY(I39,1) -> 46028 | I41: =WORKDAY(H41,J41) -> 46034 | J41: =IF(F41="New AP Lead", G41/$N$5, IF(F41="Kent", G41/$N$4, "")) -> 4 | K41: Not Started
A42: Sprint 3 | B42: Mandate | C42: Data Mapping, Data Migration & Create Tables in DB | D42: Development | E42: Data Migration - Development | F42: New AP Lead | G42: 4 | H42: =WORKDAY(I41,1) -> 46035 | I42: =WORKDAY(H42,J42) -> 46041 | J42: =IF(F42="New AP Lead", G42/$N$5, IF(F42="Kent", G42/$N$4, "")) -> 4 | K42: Not Started
A43: Sprint 4 | B43: Mandate | C43: Data Mapping, Data Migration & Create Tables in DB | D43: Development | E43: Create Tables in DB - Development | F43: New AP Lead | G43: 2 | H43: =WORKDAY(I42,1) -> 46042 | I43: =WORKDAY(H43,J43) -> 46044 | J43: =IF(F43="New AP Lead", G43/$N$5, IF(F43="Kent", G43/$N$4, "")) -> 2 | K43: Not Started
A44: Sprint 5 | B44: Mandate | C44: Data Mapping, Data Migration & Create Tables in DB | D44: QA | E44: Data Related QA - unit testing | F44: New AP Lead | G44: 3 | H44: =WORKDAY(I43,1) -> 46045 | I44: =WORKDAY(H44,J44) -> 46050 | J44: =IF(F44="New AP Lead", G44/$N$5, IF(F44="Kent", G44/$N$4, "")) -> 3 | K44: Not Started
...

Sheet Shareholders' Meeting & Managem
C1: Shareholders' Meeting & Managem
B3: TOTAL TASKS | C3: =COUNTA(E17:E1048576) -> 23 | G3: DURATION | H3: =H5-H4+1 -> 61 | J3: Overall Progress
B4: Completed | C4: =COUNTIF(L17:L1048576,B4) -> 0 | G4: START | H4: =MIN(I11:I1048576) -> 46447 | L4: =SUM(H11:H16) -> 12 | N4: Team Member | O4: FTE | P4: Cost / Monthly | T4: Difficulty Level | U4: MD
B5: In progress | C5: =COUNTIF(L17:L1048576,B5) -> 0 | G5: FINISH | H5: =MAX(J11:J1048576) -> 46507 | L5: =SUM(H11:H215) -> 52 | N5: Kent | O5: 1 | Q5: 1 year | T5: Low | U5: 1-2
B6: Not Started | C6: =COUNTIF(L17:L1048576,B6) -> 24 | N6: BA/Testing | O6: 1 | P6: =145000*1.05 -> 152250 | Q6: =P6*12 -> 1827000 | T6: Mid | U6: 3-5
D7: New SA and Engineer training | H7: 1/5/2026 - 1/9/2026 | J7: =1-J5 -> 1 | N7: AP Lead | O7: 1 | Q7: Onboard after Chinese New Year | T7: High | U7: 6-8
N8: FrontEnd1 | O8: 1 | P8: =145000*1.05 -> 152250 | Q8: =P8*12 -> 1827000
A9: SPRINT | B9: EPIC | C9: FEATURE | D9: TASKS | E9: STORIES | F9: Difficulty Level | G9: RESPONSIBLE | H9: Man Day Required | I9: START | J9: FINISH | K9: DURATION | L9: STATUS
A10: Sprint 24 | B10: Shareholders' Meeting & Management | C10: Generate Shareholder Meeting Data | D10: BA | E10: Generate Shareholder Meeting Data Requirement Analysis | F10: Low | G10: BA/Testing | H10: 1 | I10: 46447 | J10: 46447 | K10: 1 | L10: Not Started
A11: Sprint 24 | B11: Shareholders' Meeting & Management | C11: Generate Shareholder Meeting Data | D11: BA | E11: Generate Shareholder Meeting Data Requirement | F11: Low | G11: BA/Testing | H11: 1 | I11: 46448 | J11: 46448 | K11: 1 | L11: Not Started
A12: Sprint 25 | B12: Shareholders' Meeting & Management | C12: Generate Shareholder Meeting Data | D12: Development | E12: Generate Shareholder Meeting Data - Development 1 | F12: Mid | G12: FrontEnd | H12: 3 | I12: 46449 | J12: 46451 | K12: 3 | L12: Not Started
A13: Sprint 25 | B13: Shareholders' Meeting & Management | C13: Generate Shareholder Meeting Data | D13: Development | E13: Generate Shareholder Meeting Data - Development 2 | F13: Mid | G13: Kent | H13: 4 | I13: 46449 | J13: 46454 | K13: 4 | L13: Not Started
A14: Sprint 25 | B14: Shareholders' Meeting & Management | C14: Generate Shareholder Meeting Data | D14: Testing | E14: Generate Shareholder Meeting Data QA - unit-testing | F14: Low | G14: BA/Testing | H14: 2 | I14: 46455 | J14: 46456 | K14: 2 | L14: Not Started
A15: Sprint 26 | B15: Shareholders' Meeting & Management | C15: Generate Memo for Assigned Personnel/Function | D15: BA | E15: Generate Memo for Assigned Personnel/Function Requirement Analysis | F15: Low | G15: BA/Testing | H15: 1 | I15: 46447 | J15: 46447 | K15: 1 | L15: Not Started
A16: Sprint 26 | B16: Shareholders' Meeting & Management | C16: Generate Memo for Assigned Personnel/Function | D16: BA | E16: Generate Memo for Assigned Personnel/Function Requirement | F16: Low | G16: BA/Testing | H16: 1 | I16: 46448 | J16: 46448 | K16: 1 | L16: Not Started
A17: Sprint 26 | B17: Shareholders' Meeting & Management | C17: Generate Memo for Assigned Personnel/Function | D17: Development | E17: Generate Memo for Assigned Personnel/Function - Development 1 | F17: Low | G17: FrontEnd | H17: 2 | I17: 46449 | J17: 46450 | K17: 2 | L17: Not Started
A18: Sprint 26 | B18: Shareholders' Meeting & Management | C18: Generate Memo for Assigned Personnel/Function | D18: Development | E18: Generate Memo for Assigned Personnel/Function - Development 2 | F18: Mid | G18: New AP Lead | H18: 5 | I18: 46449 | J18: 46455 | K18: 5 | L18: Not Started
A19: Sprint 27 | B19: Shareholders' Meeting & Management | C19: Generate Memo for Assigned Personnel/Function | D19: Testing | E19: Generate Memo for Assigned Personnel/Function QA - unit-testing | F19: Low | G19: BA/Testing | H19: 1 | I19: 46456 | J19: 46456 | K19: 1 | L19: Not Started
A20: Sprint 27 | B20: Shareholders' Meeting & Management | C20: Director/Supervisor Election Report/Function | D20: BA | E20: Director/Supervisor Election Report/Function Requirement Analysis | F20: Low | G20: BA/Testing | H20: 1 | I20: 46451 | J20: 46451 | K20: 1 | L20: Not Started
A21: Sprint 27 | B21: Shareholders' Meeting & Management | C21: Director/Supervisor Election Report/Function | D21: BA | E21: Director/Supervisor Election Report/Function Requirement | F21: Low | G21: BA/Testing | H21: 1 | I21: 46454 | J21: 46454 | K21: 1 | L21: Not Started
... A39: Sprint 30 | B39: Shareholders' Meeting & Management | C39: Stock Basic Data Maintenance | D39: Testing | E39: Stock Basic Data Maintenance QA - unit-testing | F39: Low | G39: BA/Testing | H39: 1 | I39: 46472 | J39: 46472 | K39: 1 | L39: Not Started
A40: Sprint30 | B40: Shareholders' Meeting & Management | C40: Pararell Run | D40: All | G40: New AP Lead | I40: 46475 | J40: 46507 | L40: Not Started

Sheet Project Planning - C
C1: DMS Development
B3: TOTAL TASKS | C3: =COUNTA(E16:E1048576) -> 199 | F3: DURATION | G3: =G5-G4+1 -> 479 | I3: Overall Progress | M3: Team Member | N3: FTE
B4: Completed | C4: =COUNTIF(K16:K1048576,B4) -> 0 | F4: START | G4: =MIN(H10:H1048576) -> 45915 | K4: =SUM(G10:G15) -> 24 | M4: Patrick | N4: 0.5
B5: In progress | C5: =COUNTIF(K16:K1048576,B5) -> 9 | F5: FINISH | G5: =MAX(I10:I1048576) -> 46393 | K5: =SUM(G10:G214) -> 408 | M5: Kent | N5: 1
B6: Not Started | C6: =COUNTIF(K16:K1048576,B6) -> 190 | M6: Richard | N6: 0.5
I7: =1-I5 -> 1 | K7: =K4/K5 -> 0.058823529 | M7: AP Lead | N7: 1
M8: FrontEnd1 | N8: 1
A9: SPRINT | B9: EPIC | C9: FEATURE | D9: TASKS | E9: STORIES | F9: RESPONSIBLE | G9: Man Day Required | H9: START | I9: FINISH | J9: DURATION | K9: STATUS
A10: Sprint 0 | B10: Shareholders' Meeting & Management | C10: Data Mapping, Data Migration & Create Tables in DB | D10: BA | E10: Data Mapping, Data Migration & Create Tables in DB Requirement Analysis | F10: Kent | G10: 3 | H10: 45915 | I10: =WORKDAY(H10,J10) -> 45918 | J10: =G10/$N$5 -> 3 | K10: Completed
A11: Sprint 0 | B11: Shareholders' Meeting & Management | C11: Data Mapping, Data Migration & Create Tables in DB | D11: BA | E11: Data Mapping, Data Migration & Create Tables in DB Requirement | F11: Kent | G11: 3 | H11: =WORKDAY(I10,1) -> 45919 | I11: =WORKDAY(H11,J11) -> 45924 | J11: =G11/$N$5 -> 3 | K11: Completed
A12: Sprint 0 | B12: Shareholders' Meeting & Management | C12: Data Mapping, Data Migration & Create Tables in DB | D12: Development | E12: Data Mapping - Development | F12: Kent | G12: 5 | H12: =WORKDAY(I11,1) -> 45925 | I12: =WORKDAY(H12,J12) -> 45932 | J12: =G12/$N$5 -> 5 | K12: Completed
A13: Sprint 0 | B13: Shareholders' Meeting & Management | C13: Data Mapping, Data Migration & Create Tables in DB | D13: Development | E13: Data Migration - Development | F13: Kent | G13: 5 | H13: =WORKDAY(I12,1) -> 45933 | I13: =WORKDAY(H13,J13) -> 45940 | J13: =G13/$N$5 -> 5 | K13: Completed
A14: Sprint 0 | B14: Shareholders' Meeting & Management | C14: Data Mapping, Data Migration & Create Tables in DB | D14: Development | E14: Create Tables in DB - Development | F14: Kent | G14: 5 | H14: =WORKDAY(I13,1) -> 45943 | I14: =WORKDAY(H14,J14) -> 45950 | J14: =G14/$N$5 -> 5 | K14: Completed
A15: Sprint 0 | B15: Shareholders' Meeting & Management | C15: Data Mapping, Data Migration & Create Tables in DB | D15: QA | E15: Data Related QA - unit testing | F15: Kent | G15: 3 | H15: =WORKDAY(I14,1) -> 45951 | I15: =WORKDAY(H15,J15) -> 45954 | J15: =G15/$N$5 -> 3 | K15: Completed
A16: {=INDEX('Sprint Calendar'!$A:$A, MATCH(1, ('Project Planning - C'!I16 >= 'Sprint Calendar'!$B:$B) * ('Project Planning - C'!H16 <= 'Sprint Calendar'!$C:$C), 0))} -> Sprint 1 | B16: Dividend Distribution | C16: Data Mapping, Data Migration & Create Tables in DB | D16: BA | E16: Data Related Detail Requirement Analysis | F16: Patrick | G16: 3 | H16: 45985 | I16: =WORKDAY(H16,J16) -> 45993 | J16: =G16/N4 -> 6 | K16: In progress
A17: {=INDEX('Sprint Calendar'!$A:$A, MATCH(1, ('Project Planning - C'!I17 >= 'Sprint Calendar'!$B:$B) * ('Project Planning - C'!H17 <= 'Sprint Calendar'!$C:$C), 0))} -> Sprint 1 | B17: Dividend Distribution | C17: Data Mapping, Data Migration & Create Tables in DB | D17: BA | E17: Data Related Document Detail Requirement | F17: Patrick | G17: 3 | H17: =WORKDAY(I16,1) -> 45994 | I17: =WORKDAY(H17,J17) -> 46002 | J17: =G17/N4 -> 6 | K17: In progress
A18: {=INDEX('Sprint Calendar'!$A:$A, MATCH(1, ('Project Planning - C'!I18 >= 'Sprint Calendar'!$B:$B) * ('Project Planning - C'!H18 <= 'Sprint Calendar'!$C:$C), 0))} -> Sprint 1 | B18: Dividend Distribution | C18: Data Mapping, Data Migration & Create Tables in DB | D18: Development | E18: Data Mapping - Development | F18: Kent | G18: 3 | H18: 45985 | I18: =WORKDAY(H18,J18) -> 45988 | J18: =G18/$N$5 -> 3 | K18: In progress
A19: {=INDEX('Sprint Calendar'!$A:$A, MATCH(1, ('Project Planning - C'!I19 >= 'Sprint Calendar'!$B:$B) * ('Project Planning - C'!H19 <= 'Sprint Calendar'!$C:$C), 0))} -> Sprint 1 | B19: Dividend Distribution | C19: Data Mapping, Data Migration & Create Tables in DB | D19: Development | E19: Data Migration - Development | F19: Kent | G19: 5 | H19: =WORKDAY(I18,1) -> 45989 | I19: =WORKDAY(H19,J19) -> 45996 | J19: =G19/$N$5 -> 5 | K19: Not Started
A20: {=INDEX('Sprint Calendar'!$A:$A, MATCH(1, ('Project Planning - C'!I20 >= 'Sprint Calendar'!$B:$B) * ('Project Planning - C'!H20 <= 'Sprint Calendar'!$C:$C), 0))} -> Sprint 2 | B20: Dividend Distribution | C20: Data Mapping, Data Migration & Create Tables in DB | D20: Development | E20: Create Tables in DB - Development | F20: Kent | G20: 2 | H20: =WORKDAY(I19,1) -> 45999 | I20: =WORKDAY(H20,J20) -> 46001 | J20: =G20/$N$5 -> 2 | K20: Not Started
A21: {=INDEX('Sprint Calendar'!$A:$A, MATCH(1, ('Project Planning - C'!I21 >= 'Sprint Calendar'!$B:$B) * ('Project Planning - C'!H21 <= 'Sprint Calendar'!$C:$C), 0))} -> Sprint 2 | B21: Dividend Distribution | C21: Data Mapping, Data Migration & Create Tables in DB | D21: QA | E21: Data Related QA - unit testing | F21: Kent | G21: 3 | H21: =WORKDAY(I20,1) -> 46002 | I21: =WORKDAY(H21,J21) -> 46007 | J21: =G21/N5 -> 3 | K21: Not Started
A22: {=INDEX('Sprint Calendar'!$A:$A, MATCH(1, ('Project Planning - C'!I22 >= 'Sprint Calendar'!$B:$B) * ('Project Planning - C'!H22 <= 'Sprint Calendar'!$C:$C), 0))} -> Sprint 2 | B22: Dividend Distribution | C22: Maintain Distributable Balance 可分配餘額維護作業 | D22: BA | E22: Maintain Distributable Balance Detail Requirement Analysis | F22: Patrick | G22: 1.5 | H22: =WORKDAY(I17,1) -> 46003 | I22: =WORKDAY(H22,J22) -> 46008 | J22: =G22/$N$6 -> 3 | K22: In progress
A23: {=INDEX('Sprint Calendar'!$A:$A, MATCH(1, ('Project Planning - C'!I23 >= 'Sprint Calendar'!$B:$B) * ('Project Planning - C'!H23 <= 'Sprint Calendar'!$C:$C), 0))} -> Sprint 2 | B23: Dividend Distribution | C23: Maintain Distributable Balance 可分配餘額維護作業 | D23: BA | E23: Maintain Distributable Document Detail Requirement | F23: Patrick | G23: 1.5 | H23: =WORKDAY(I22,1) -> 46009 | I23: =WORKDAY(H23,J23) -> 46014 | J23: =G23/$N$6 -> 3 | K23: In progress
A24: {=INDEX('Sprint Calendar'!$A:$A, MATCH(1, ('Project Planning - C'!I24 >= 'Sprint Calendar'!$B:$B) * ('Project Planning - C'!H24 <= 'Sprint Calendar'!$C:$C), 0))} -> Sprint 2 | B24: Dividend Distribution | C24: Maintain Distributable Balance 可分配餘額維護作業 | D24: Development | E24: Maintain Distributable Balance - Development 1 | F24: Kent | G24: 4 | H24: =WORKDAY(I21,1) -> 46008 | I24: =WORKDAY(H24,J24) -> 46014 | J24: =G24/$N$5 -> 4 | K24: Not Started
A25: {=INDEX('Sprint Calendar'!$A:$A, MATCH(1, ('Project Planning - C'!I25 >= 'Sprint Calendar'!$B:$B) * ('Project Planning - C'!H25 <= 'Sprint Calendar'!$C:$C), 0))} -> Sprint 3 | B25: Dividend Distribution | C25: Maintain Distributable Balance 可分配餘額維護作業 | D25: Development | E25: Maintain Distributable Balance - Development 2 | F25: Kent | G25: 4 | H25: =WORKDAY(I24,1) -> 46015 | I25: =WORKDAY(H25,J25) -> 46021 | J25: =G25/$N$5 -> 4 | K25: Not Started
A26: {=INDEX('Sprint Calendar'!$A:$A, MATCH(1, ('Project Planning - C'!I26 >= 'Sprint Calendar'!$B:$B) * ('Project Planning - C'!H26 <= 'Sprint Calendar'!$C:$C), 0))} -> Sprint 3 | B26: Dividend Distribution | C26: Maintain Distributable Balance 可分配餘額維護作業 | D26: QA | E26: Maintain Distributable Balance QA - unit testing | F26: Kent | G26: 3 | H26: =WORKDAY(I25,1) -> 46022 | I26: =WORKDAY(H26,J26) -> 46027 | J26: =G26/$N$5 -> 3 | K26: Not Started
A27: {=INDEX('Sprint Calendar'!$A:$A, MATCH(1, ('Project Planning - C'!I27 >= 'Sprint Calendar'!$B:$B) * ('Project Planning - C'!H27 <= 'Sprint Calendar'!$C:$C), 0))} -> Sprint 3 | B27: Dividend Distribution | C27: Domestic Dividend Information Inquiry 境內配息資訊查詢作業 | D27: BA | E27: Domestic Dividend Information Inquiry Detail Requirement Analysis | F27: Patrick | G27: 1.5 | H27: =WORKDAY(I23,1) -> 46015 | I27: =WORKDAY(H27,J27) -> 46020 | J27: =G27/$N$4 -> 3 | K27: In progress
A28: {=INDEX('Sprint Calendar'!$A:$A, MATCH(1, ('Project Planning - C'!I28 >= 'Sprint Calendar'!$B:$B) * ('Project Planning - C'!H28 <= 'Sprint Calendar'!$C:$C), 0))} -> Sprint 3 | B28: Dividend Distribution | C28: Domestic Dividend Information Inquiry 境內配息資訊查詢作業 | D28: BA | E28: Domestic Dividend Information Inquiry Document Detail Requirement | F28: Patrick | G28: 1.5 | H28: =WORKDAY(I27,1) -> 46021 | I28: =WORKDAY(H28,J28) -> 46024 | J28: =G28/$N$4 -> 3 | K28: In progress
A29: {=INDEX('Sprint Calendar'!$A:$A, MATCH(1, ('Project Planning - C'!I29 >= 'Sprint Calendar'!$B:$B) * ('Project Planning - C'!H29 <= 'Sprint Calendar'!$C:$C), 0))} -> Sprint 4 | B29: Dividend Distribution | C29: Domestic Dividend Information Inquiry 境內配息資訊查詢作業 | D29: Development | E29: Domestic Dividend Information Inquiry - Development 1 | F29: Kent | G29: 4 | H29: =WORKDAY(I26,1) -> 46028 | I29: =WORKDAY(H29,J29) -> 46034 | J29: =G29/$N$5 -> 4 | K29: Not Started
A30: {=INDEX('Sprint Calendar'!$A:$A, MATCH(1, ('Project Planning - C'!I30 >= 'Sprint Calendar'!$B:$B) * ('Project Planning - C'!H30 <= 'Sprint Calendar'!$C:$C), 0))} -> Sprint 4 | B30: Dividend Distribution | C30: Domestic Dividend Information Inquiry 境內配息資訊查詢作業 | D30: Development | E30: Domestic Dividend Information Inquiry - Development 2 | F30: Kent | G30: 4 | H30: =WORKDAY(I29,1) -> 46035 | I30: =WORKDAY(H30,J30) -> 46041 | J30: =G30/$N$5 -> 4 | K30: Not Started
A31: {=INDEX('Sprint Calendar'!$A:$A, MATCH(1, ('Project Planning - C'!I31 >= 'Sprint Calendar'!$B:$B) * ('Project Planning - C'!H31 <= 'Sprint Calendar'!$C:$C), 0))} -> Sprint 5 | B31: Dividend Distribution | C31: Domestic Dividend Information Inquiry 境內配息資訊查詢作業 | D31: QA | E31: Domestic Dividend Information Inquiry QA - unit testing | F31: Kent | G31: 2 | H31: =WORKDAY(I30,1) -> 46042 | I31: =WORKDAY(H31,J31) -> 46044 | J31: =G31/$N$5 -> 2 | K31: Not Started
A32: {=INDEX('Sprint Calendar'!$A:$A, MATCH(1, ('Project Planning - C'!I32 >= 'Sprint Calendar'!$B:$B) * ('Project Planning - C'!H32 <= 'Sprint Calendar'!$C:$C), 0))} -> Sprint 3 | B32: Dividend Distribution | C32: Upload Domestic Dividend Composition Info to EC 境內配息組成資訊上傳EC | D32: BA | E32: Upload Domestic Dividend Composition Info to EC - Detail Requirement Analysis | F32: Patrick | G32: 1.5 | H32: =WORKDAY(I23,1) -> 46015 | I32: =WORKDAY(H32,J32) -> 46020 | J32: =G32/$N$4 -> 3 | K32: In progress
A33: {=INDEX('Sprint Calendar'!$A:$A, MATCH(1, ('Project Planning - C'!I33 >= 'Sprint Calendar'!$B:$B) * ('Project Planning - C'!H33 <= 'Sprint Calendar'!$C:$C), 0))} -> Sprint 3 | B33: Dividend Distribution | C33: Upload Domestic Dividend Composition Info to EC 境內配息組成資訊上傳EC | D33: BA | E33: Upload Domestic Dividend Composition Info to EC - Document Detail Requirement | F33: Patrick | G33: 1.5 | H33: =WORKDAY(I32,1) -> 46021 | I33: =WORKDAY(H33,J33) -> 46024 | J33: =G33/$N$4 -> 3 | K33: In progress
A34: {=INDEX('Sprint Calendar'!$A:$A, MATCH(1, ('Project Planning - C'!I34 >= 'Sprint Calendar'!$B:$B) * ('Project Planning - C'!H34 <= 'Sprint Calendar'!$C:$C), 0))} -> Sprint 5 | B34: Dividend Distribution | C34: Upload Domestic Dividend Composition Info to EC 境內配息組成資訊上傳EC | D34: Development | E34: Upload Domestic Dividend Composition Info to EC - Development 1 | F34: Kent | G34: 4 | H34: =WORKDAY(I31,1) -> 46045 | I34: =WORKDAY(H34,J34) -> 46051 | J34: =G34/$N$5 -> 4 | K34: Not Started
A35: {=INDEX('Sprint Calendar'!$A:$A, MATCH(1, ('Project Planning - C'!I35 >= 'Sprint Calendar'!$B:$B) * ('Project Planning - C'!H35 <= 'Sprint Calendar'!$C:$C), 0))} -> Sprint 5 | B35: Dividend Distribution | C35: Upload Domestic Dividend Composition Info to EC 境內配息組成資訊上傳EC | D35: Development | E35: Upload Domestic Dividend Composition Info to EC - Development 2 | F35: Kent | G35: 4 | H35: =WORKDAY(I34,1) -> 46052 | I35: =WORKDAY(H35,J35) -> 46058 | J35: =G35/$N$5 -> 4 | K35: Not Started
A36: {=INDEX('Sprint Calendar'!$A:$A, MATCH(1, ('Project Planning - C'!I36 >= 'Sprint Calendar'!$B:$B) * ('Project Planning - C'!H36 <= 'Sprint Calendar'!$C:$C), 0))} -> Sprint 6 | B36: Dividend Distribution | C36: Upload Domestic Dividend Composition Info to EC 境內配息組成資訊上傳EC | D36: QA | E36: Upload Domestic Dividend Composition Info to EC QA - unit testing | F36: Kent | G36: 2 | H36: =WORKDAY(I35,1) -> 46059 | I36: =WORKDAY(H36,J36) -> 46063 | J36: =G36/$N$5 -> 2 | K36: Not Started
A37: {=INDEX('Sprint Calendar'!$A:$A, MATCH(1, ('Project Planning - C'!I37 >= 'Sprint Calendar'!$B:$B) * ('Project Planning - C'!H37 <= 'Sprint Calendar'!$C:$C), 0))} -> Sprint 1 | B37: Mandate | C37: Data Mapping, Data Migration & Create Tables in DB | D37: BA | E37: Data Mapping, Data Migration & Create Tables in DB Requirement Analysis | F37: Richard | G37: 3 | H37: 45992 | I37: =WORKDAY(H37,J37) -> 46000 | J37: =G37/$N$6 -> 6 | K37: Not Started
A38: {=INDEX('Sprint Calendar'!$A:$A, MATCH(1, ('Project Planning - C'!I38 >= 'Sprint Calendar'!$B:$B) * ('Project Planning - C'!H38 <= 'Sprint Calendar'!$C:$C), 0))} -> Sprint 2 | B38: Mandate | C38: Data Mapping, Data Migration & Create Tables in DB | D38: BA | E38: Data Mapping, Data Migration & Create Tables in DB Requirement | F38: Richard | G38: 3 | H38: =WORKDAY(I37,1) -> 46001 | I38: =WORKDAY(H38,J38) -> 46009 | J38: =G38/$N$6 -> 6 | K38: Not Started
A39: {=INDEX('Sprint Calendar'!$A:$A, MATCH(1, ('Project Planning - C'!I39 >= 'Sprint Calendar'!$B:$B) * ('Project Planning - C'!H39 <= 'Sprint Calendar'!$C:$C), 0))} -> Sprint 2 | B39: Mandate | C39: Data Mapping, Data Migration & Create Tables in DB | D39: Development | E39: Data Mapping - Development | F39: Richard | G39: 4 | H39: =WORKDAY(I38,1) -> 46010 | I39: =WORKDAY(H39,J39) -> 46022 | J39: =G39/$N$6 -> 8 | K39: Not Started
A40: {=INDEX('Sprint Calendar'!$A:$A, MATCH(1, ('Project Planning - C'!I40 >= 'Sprint Calendar'!$B:$B) * ('Project Planning - C'!H40 <= 'Sprint Calendar'!$C:$C), 0))} -> Sprint 3 | B40: Mandate | C40: Data Mapping, Data Migration & Create Tables in DB | D40: Development | E40: Data Migration - Development | F40: Richard | G40: 4 | H40: =WORKDAY(I39,1) -> 46023 | I40: =WORKDAY(H40,J40) -> 46035 | J40: =G40/$N$6 -> 8 | K40: Not Started
A41: {=INDEX('Sprint Calendar'!$A:$A, MATCH(1, ('Project Planning - C'!I41 >= 'Sprint Calendar'!$B:$B) * ('Project Planning - C'!H41 <= 'Sprint Calendar'!$C:$C), 0))} -> Sprint 4 | B41: Mandate | C41: Data Mapping, Data Migration & Create Tables in DB | D41: Development | E41: Create Tables in DB - Development | F41: Richard | G41: 2 | H41: =WORKDAY(I40,1) -> 46036 | I41: =WORKDAY(H41,J41) -> 46042 | J41: =G41/$N$6 -> 4 | K41: Not Started
...

Sheet Project Planning (3)
C1: DMS Development
B3: TOTAL TASKS | C3: =COUNTA(E16:E1048576) -> 199 | F3: DURATION | G3: =G5-G4+1 -> 325 | I3: Overall Progress | M3: Team Member | N3: FTE
B4: Completed | C4: =COUNTIF(K16:K1048576,B4) -> 0 | F4: START | G4: =MIN(H10:H1048576) -> 45915 | K4: =SUM(G10:G15) -> 24 | M4: BA | N4: 1
B5: In progress | C5: =COUNTIF(K16:K1048576,B5) -> 9 | F5: FINISH | G5: =MAX(I10:I1048576) -> 46239 | K5: =SUM(G10:G214) -> 408 | M5: Kent | N5: 1
B6: Not Started | C6: =COUNTIF(K16:K1048576,B6) -> 190 | M6: QA | N6: 1
I7: =1-I5 -> 1 | K7: =K4/K5 -> 0.058823529 | M7: AP Lead | N7: 1
M8: FrontEnd | N8: 1
A9: SPRINT | B9: EPIC | C9: FEATURE | D9: TASKS | E9: STORIES | F9: RESPONSIBLE | G9: Man Day Required | H9: START | I9: FINISH | J9: DURATION | K9: STATUS
A10: Sprint 0 | B10: Shareholders' Meeting & Management | C10: Data Mapping, Data Migration & Create Tables in DB | D10: BA | E10: Data Mapping, Data Migration & Create Tables in DB Requirement Analysis | F10: BA | G10: 3 | H10: 45915 | I10: =WORKDAY(H10,J10) -> 45918 | J10: =G10/$N$5 -> 3 | K10: Completed
A11: Sprint 0 | B11: Shareholders' Meeting & Management | C11: Data Mapping, Data Migration & Create Tables in DB | D11: BA | E11: Data Mapping, Data Migration & Create Tables in DB Requirement | F11: BA | G11: 3 | H11: =WORKDAY(I10,1) -> 45919 | I11: =WORKDAY(H11,J11) -> 45924 | J11: =G11/$N$5 -> 3 | K11: Completed
A12: Sprint 0 | B12: Shareholders' Meeting & Management | C12: Data Mapping, Data Migration & Create Tables in DB | D12: Development | E12: Data Mapping - Development | F12: Kent | G12: 5 | H12: =WORKDAY(I11,1) -> 45925 | I12: =WORKDAY(H12,J12) -> 45932 | J12: =G12/$N$5 -> 5 | K12: Completed
A13: Sprint 0 | B13: Shareholders' Meeting & Management | C13: Data Mapping, Data Migration & Create Tables in DB | D13: Development | E13: Data Migration - Development | F13: Kent | G13: 5 | H13: =WORKDAY(I12,1) -> 45933 | I13: =WORKDAY(H13,J13) -> 45940 | J13: =G13/$N$5 -> 5 | K13: Completed
A14: Sprint 0 | B14: Shareholders' Meeting & Management | C14: Data Mapping, Data Migration & Create Tables in DB | D14: Development | E14: Create Tables in DB - Development | F14: Kent | G14: 5 | H14: =WORKDAY(I13,1) -> 45943 | I14: =WORKDAY(H14,J14) -> 45950 | J14: =G14/$N$5 -> 5 | K14: Completed
A15: Sprint 0 | B15: Shareholders' Meeting & Management | C15: Data Mapping, Data Migration & Create Tables in DB | D15: QA | E15: Data Related QA - unit testing | F15: QA | G15: 3 | H15: =WORKDAY(I14,1) -> 45951 | I15: =WORKDAY(H15,J15) -> 45954 | J15: =G15/$N$5 -> 3 | K15: Completed
A16: Sprint 1 | B16: Dividend Distribution | C16: Data Mapping, Data Migration & Create Tables in DB | D16: BA | E16: Data Related Detail Requirement Analysis | F16: BA | G16: 3 | H16: 45985 | I16: =WORKDAY(H16,J16) -> 45988 | J16: =G16/N4 -> 3 | K16: In progress
A17: Sprint 1 | B17: Dividend Distribution | C17: Data Mapping, Data Migration & Create Tables in DB | D17: BA | E17: Data Related Document Detail Requirement | F17: BA | G17: 3 | H17: =WORKDAY(I16,1) -> 45989 | I17: =WORKDAY(H17,J17) -> 45994 | J17: =G17/N4 -> 3 | K17: In progress
A18: Sprint 1 | B18: Dividend Distribution | C18: Data Mapping, Data Migration & Create Tables in DB | D18: Development | E18: Data Mapping - Development | F18: Kent | G18: 3 | H18: =WORKDAY(I17,1) -> 45995 | I18: =WORKDAY(H18,J18) -> 46000 | J18: =G18/$N$5 -> 3 | K18: In progress
A19: Sprint 1 | B19: Dividend Distribution | C19: Data Mapping, Data Migration & Create Tables in DB | D19: Development | E19: Data Migration - Development | F19: Kent | G19: 5 | H19: =WORKDAY(I18,1) -> 46001 | I19: =WORKDAY(H19,J19) -> 46008 | J19: =G19/$N$5 -> 5 | K19: Not Started
A20: Sprint 2 | B20: Dividend Distribution | C20: Data Mapping, Data Migration & Create Tables in DB | D20: Development | E20: Create Tables in DB - Development | F20: Kent | G20: 2 | H20: =WORKDAY(I19,1) -> 46009 | I20: =WORKDAY(H20,J20) -> 46013 | J20: =G20/$N$5 -> 2 | K20: Not Started
A21: Sprint 2 | B21: Dividend Distribution | C21: Data Mapping, Data Migration & Create Tables in DB | D21: QA | E21: Data Related QA - unit testing | F21: QA | G21: 3 | H21: =WORKDAY(I20,1) -> 46014 | I21: =WORKDAY(H21,J21) -> 46017 | J21: =G21/$N$5 -> 3 | K21: Not Started
A22: Sprint 2 | B22: Dividend Distribution | C22: Maintain Distributable Balance 可分配餘額維護作業 | D22: BA | E22: Maintain Distributable Balance Detail Requirement Analysis | F22: BA | G22: 1.5 | H22: =WORKDAY(I17,1) -> 45995 | I22: =WORKDAY(H22,J22) -> 45996 | J22: =G22/$N$6 -> 1.5 | K22: In progress
A23: Sprint 2 | B23: Dividend Distribution | C23: Maintain Distributable Balance 可分配餘額維護作業 | D23: BA | E23: Maintain Distributable Document Detail Requirement | F23: BA | G23: 1.5 | H23: =WORKDAY(I22,1) -> 45999 | I23: =WORKDAY(H23,J23) -> 46000 | J23: =G23/$N$6 -> 1.5 | K23: In progress
A24: Sprint 2 | B24: Dividend Distribution | C24: Maintain Distributable Balance 可分配餘額維護作業 | D24: Development | E24: Maintain Distributable Balance - Development 1 | F24: FrontEnd | G24: 4 | H24: =WORKDAY(I23,1) -> 46001 | I24: =WORKDAY(H24,J24) -> 46007 | J24: =G24/$N$5 -> 4 | K24: Not Started
A25: Sprint 3 | B25: Dividend Distribution | C25: Maintain Distributable Balance 可分配餘額維護作業 | D25: Development | E25: Maintain Distributable Balance - Development 2 | F25: Kent | G25: 4 | H25: =WORKDAY(I23,1) -> 46001 | I25: =WORKDAY(H25,J25) -> 46007 | J25: =G25/$N$5 -> 4 | K25: Not Started
A26: Sprint 3 | B26: Dividend Distribution | C26: Maintain Distributable Balance 可分配餘額維護作業 | D26: QA | E26: Maintain Distributable Balance QA - unit testing | F26: QA | G26: 3 | H26: =WORKDAY(I25,1) -> 46008 | I26: =WORKDAY(H26,J26) -> 46013 | J26: =G26/$N$5 -> 3 | K26: Not Started
A27: Sprint 3 | B27: Dividend Distribution | C27: Domestic Dividend Information Inquiry 境內配息資訊查詢作業 | D27: BA | E27: Domestic Dividend Information Inquiry Detail Requirement Analysis | F27: BA | G27: 1.5 | H27: =WORKDAY(I23,1) -> 46001 | I27: =WORKDAY(H27,J27) -> 46002 | J27: =G27/$N$4 -> 1.5 | K27: In progress
A28: Sprint 3 | B28: Dividend Distribution | C28: Domestic Dividend Information Inquiry 境內配息資訊查詢作業 | D28: BA | E28: Domestic Dividend Information Inquiry Document Detail Requirement | F28: BA | G28: 1.5 | H28: =WORKDAY(I27,1) -> 46003 | I28: =WORKDAY(H28,J28) -> 46006 | J28: =G28/$N$4 -> 1.5 | K28: In progress
A29: Sprint 4 | B29: Dividend Distribution | C29: Domestic Dividend Information Inquiry 境內配息資訊查詢作業 | D29: Development | E29: Domestic Dividend Information Inquiry - Development 1 | F29: FrontEnd | G29: 4 | H29: =WORKDAY(I28,1) -> 46007 | I29: =WORKDAY(H29,J29) -> 46013 | J29: =G29/$N$5 -> 4 | K29: Not Started
A30: Sprint 4 | B30: Dividend Distribution | C30: Domestic Dividend Information Inquiry 境內配息資訊查詢作業 | D30: Development | E30: Domestic Dividend Information Inquiry - Development 2 | F30: Kent | G30: 4 | H30: =WORKDAY(I28,1) -> 46007 | I30: =WORKDAY(H30,J30) -> 46013 | J30: =G30/$N$5 -> 4 | K30: Not Started
A31: Sprint 5 | B31: Dividend Distribution | C31: Domestic Dividend Information Inquiry 境內配息資訊查詢作業 | D31: QA | E31: Domestic Dividend Information Inquiry QA - unit testing | F31: QA | G31: 2 | H31: =WORKDAY(I30,1) -> 46014 | I31: =WORKDAY(H31,J31) -> 46016 | J31: =G31/$N$5 -> 2 | K31: Not Started
A32: Sprint 3 | B32: Dividend Distribution | C32: Upload Domestic Dividend Composition Info to EC 境內配息組成資訊上傳EC | D32: BA | E32: Upload Domestic Dividend Composition Info to EC - Detail Requirement Analysis | F32: BA | G32: 1.5 | H32: =WORKDAY(I28,1) -> 46007 | I32: =WORKDAY(H32,J32) -> 46008 | J32: =G32/$N$4 -> 1.5 | K32: In progress
A33: Sprint 3 | B33: Dividend Distribution | C33: Upload Domestic Dividend Composition Info to EC 境內配息組成資訊上傳EC | D33: BA | E33: Upload Domestic Dividend Composition Info to EC - Document Detail Requirement | F33: BA | G33: 1.5 | H33: =WORKDAY(I32,1) -> 46009 | I33: =WORKDAY(H33,J33) -> 46010 | J33: =G33/$N$4 -> 1.5 | K33: In progress
A34: Sprint 5 | B34: Dividend Distribution | C34: Upload Domestic Dividend Composition Info to EC 境內配息組成資訊上傳EC | D34: Development | E34: Upload Domestic Dividend Composition Info to EC - Development 1 | F34: FrontEnd | G34: 4 | H34: 46014 | I34: =WORKDAY(H34,J34) -> 46020 | J34: =G34/$N$5 -> 4 | K34: Not Started
A35: Sprint 5 | B35: Dividend Distribution | C35: Upload Domestic Dividend Composition Info to EC 境內配息組成資訊上傳EC | D35: Development | E35: Upload Domestic Dividend Composition Info to EC - Development 2 | F35: Kent | G35: 4 | H35: 46014 | I35: =WORKDAY(H35,J35) -> 46020 | J35: =G35/$N$5 -> 4 | K35: Not Started
A36: Sprint 6 | B36: Dividend Distribution | C36: Upload Domestic Dividend Composition Info to EC 境內配息組成資訊上傳EC | D36: QA | E36: Upload Domestic Dividend Composition Info to EC QA - unit testing | F36: QA | G36: 2 | H36: =WORKDAY(I35,1) -> 46021 | I36: =WORKDAY(H36,J36) -> 46023 | J36: =G36/$N$5 -> 2 | K36: Not Started
A37: Sprint 1 | B37: Mandate | C37: Data Mapping, Data Migration & Create Tables in DB | D37: BA | E37: Data Mapping, Data Migration & Create Tables in DB Requirement Analysis | F37: BA | G37: 3 | H37: =WORKDAY(I33,1) -> 46013 | I37: =WORKDAY(H37,J37) -> 46016 | J37: =G37/$N$6 -> 3 | K37: Not Started
A38: Sprint 2 | B38: Mandate | C38: Data Mapping, Data Migration & Create Tables in DB | D38: BA | E38: Data Mapping, Data Migration & Create Tables in DB Requirement | F38: BA | G38: 3 | H38: =WORKDAY(I37,1) -> 46017 | I38: =WORKDAY(H38,J38) -> 46022 | J38: =G38/$N$6 -> 3 | K38: Not Started
A39: Sprint 2 | B39: Mandate | C39: Data Mapping, Data Migration & Create Tables in DB | D39: Development | E39: Data Mapping - Development | F39: New AP Lead | G39: 4 | H39: 46024 | I39: =WORKDAY(H39,J39) -> 46030 | J39: =G39/$N$7 -> 4 | K39: Not Started
A40: Sprint 3 | B40: Mandate | C40: Data Mapping, Data Migration & Create Tables in DB | D40: Development | E40: Data Migration - Development | F40: New AP Lead | G40: 4 | H40: =WORKDAY(I39,1) -> 46031 | I40: =WORKDAY(H40,J40) -> 46037 | J40: =G40/$N$7 -> 4 | K40: Not Started
A41: Sprint 4 | B41: Mandate | C41: Data Mapping, Data Migration & Create Tables in DB | D41: Development | E41: Create Tables in DB - Development | F41: New AP Lead | G41: 2 | H41: =WORKDAY(I40,1) -> 46038 | I41: =WORKDAY(H41,J41) -> 46042 | J41: =G41/$N$7 -> 2 | K41: Not Started
...

Sheet Sprint Calendar
A1: Sprint | B1: Start Date | C1: End Date
A2: Sprint 1 | B2: 45985 | C2: 45998
A3: Sprint 2 | B3: 45999 | C3: 46012
A4: Sprint 3 | B4: 46013 | C4: 46026
A5: Sprint 4 | B5: 46027 | C5: 46040
A6: Sprint 5 | B6: 46041 | C6: 46054
A7: Sprint 6 | B7: 46055 | C7: 46068
A8: Sprint 7 | B8: 46069 | C8: 46082
A9: Sprint 8 | B9: 46083 | C9: 46096
A10: Sprint 9 | B10: 46097 | C10: 46110
A11: Sprint 10 | B11: 46111 | C11: 46124
A12: Sprint 11 | B12: 46125 | C12: 46138
A13: Sprint 12 | B13: 46139 | C13: 46152
... A34: Sprint 33 | B34: 46440 | C34: 46451

Sheet Project Planning (2)
C1: DMS Development
B3: TOTAL TASKS | C3: =COUNTA(E15:E1048576) -> 199 | F3: DURATION | G3: =G5-G4+1 -> #DIV/0! | I3: Overall Progress | M3: Team Member | N3: FTE
B4: Completed | C4: =COUNTIF(K15:K1048576,B4) -> 4 | F4: START | G4: =MIN(H9:H1048576) -> #DIV/0! | K4: =SUM(G9:G14) -> 15 | M4: BA | N4: 1
B5: In progress | C5: =COUNTIF(K15:K1048576,B5) -> 5 | F5: FINISH | G5: =MAX(I9:I1048576) -> #DIV/0! | K5: =SUM(G9:G213) -> 408 | M5: Kent | N5: 1
B6: Not Started | C6: =COUNTIF(K15:K1048576,B6) -> 190 | M6: QA | N6: 1
I7: =1-I5 -> 1 | K7: =K4/K5 -> 0.036764706 | M7: AP Lead | N7: 1
A8: SPRINT | B8: EPIC | C8: FEATURE | D8: TASKS | E8: STORIES | F8: RESPONSIBLE | G8: Man Day Required | H8: START | I8: FINISH | J8: DURATION | K8: STATUS
A9: Sprint 0 | B9: Shareholders' Meeting & Management | C9: Data Mapping, Data Migration & Create Tables in DB | D9: BA | E9: Data Mapping, Data Migration & Create Tables in DB Requirement Analysis | F9: Kent | G9: 3 | H9: 45915 | I9: =WORKDAY(H9,J9) -> 45918 | J9: =G9/$N$4 -> 3 | K9: Completed
A10: Sprint 0 | B10: Shareholders' Meeting & Management | C10: Data Mapping, Data Migration & Create Tables in DB | D10: BA | E10: Data Mapping, Data Migration & Create Tables in DB Requirement | F10: Kent | G10: 3 | H10: =WORKDAY(I9,1) -> 45919 | I10: =WORKDAY(H10,J10) -> 45924 | J10: =G10/$N$4 -> 3 | K10: Completed
A11: {=INDEX('Sprint Calendar'!$A:$A, MATCH(1, ('Project Planning (2)'!I15 >= 'Sprint Calendar'!$B:$B) * ('Project Planning (2)'!H15 <= 'Sprint Calendar'!$C:$C), 0))} -> Sprint 5 | B11: Dividend Distribution | C11: Data Mapping, Data Migration & Create Tables in DB | D11: BA | E11: Data Related Detail Requirement Analysis | F11: BA | G11: 3 | H11: 46023 | I11: =WORKDAY(H11,J11) -> 46028 | J11: =G11/$N$4 -> 3 | K11: In progress
A12: {=INDEX('Sprint Calendar'!$A:$A, MATCH(1, ('Project Planning (2)'!I16 >= 'Sprint Calendar'!$B:$B) * ('Project Planning (2)'!H16 <= 'Sprint Calendar'!$C:$C), 0))} -> Sprint 5 | B12: Dividend Distribution | C12: Data Mapping, Data Migration & Create Tables in DB | D12: BA | E12: Data Related Document Detail Requirement | F12: BA | G12: 3 | H12: =WORKDAY(I11,1) -> 46029 | I12: =WORKDAY(H12,J12) -> 46034 | J12: =G12/$N$4 -> 3 | K12: In progress
A13: {=INDEX('Sprint Calendar'!$A:$A, MATCH(1, ('Project Planning (2)'!I21 >= 'Sprint Calendar'!$B:$B) * ('Project Planning (2)'!H21 <= 'Sprint Calendar'!$C:$C), 0))} -> Sprint 6 | B13: Dividend Distribution | C13: Maintain Distributable Balance 可分配餘額維護作業 | D13: BA | E13: Maintain Distributable Balance Detail Requirement Analysis | F13: BA | G13: 1.5 | H13: =WORKDAY(I12,1) -> 46035 | I13: =WORKDAY(H13,J13) -> 46036 | J13: =G13/$N$4 -> 1.5 | K13: In progress
A14: {=INDEX('Sprint Calendar'!$A:$A, MATCH(1, ('Project Planning (2)'!I22 >= 'Sprint Calendar'!$B:$B) * ('Project Planning (2)'!H22 <= 'Sprint Calendar'!$C:$C), 0))} -> Sprint 6 | B14: Dividend Distribution | C14: Maintain Distributable Balance 可分配餘額維護作業 | D14: BA | E14: Maintain Distributable Document Detail Requirement | F14: BA | G14: 1.5 | H14: =WORKDAY(I13,1) -> 46037 | I14: =WORKDAY(H14,J14) -> 46038 | J14: =G14/$N$4 -> 1.5 | K14: In progress
A15: {=INDEX('Sprint Calendar'!$A:$A, MATCH(1, ('Project Planning (2)'!I26 >= 'Sprint Calendar'!$B:$B) * ('Project Planning (2)'!H26 <= 'Sprint Calendar'!$C:$C), 0))} -> Sprint 8 | B15: Dividend Distribution | C15: Domestic Dividend Information Inquiry 境內配息資訊查詢作業 | D15: BA | E15: Domestic Dividend Information Inquiry Detail Requirement Analysis | F15: BA | G15: 1.5 | H15: =WORKDAY(I14,1) -> 46041 | I15: =WORKDAY(H15,J15) -> 46042 | J15: =G15/$N$4 -> 1.5 | K15: In progress
